{"task": "Summarize logs for debugging", "logs_preview": "===== logs/app.log =====\n2025-09-07 10:00:01 INFO Starting server on port 8000\n2025-09-07 10:00:03 WARNING Cache miss for key=user:123\n2025-09-07 10:00:05 ERROR Database connection failed: timeout after 5s\nTraceback (most recent call last):\n\n2025-09-07 10:00:01 INFO Starting server on port 8000\n2025-09-07 10:00:03 WARNING Cache miss for key=user:123\n2025-09-07 10:00:05 ERROR Database connection failed: timeout after 5s\nTraceback (most recent call last):\n  File \"/app/service.py\", line 42, in connect\n\n2025-09-07 10:00:03 WARNING Cache miss for key=user:123\n2025-09-07 10:00:05 ERROR Database connection failed: timeout after 5s\nTraceback (most recent call last):\n  File \"/app/service.py\", line 42, in connect\n    client = db.connect(url)\n\n    client = db.connect(url)\n  File \"/app/db.py\", line 10, in connect\n    raise TimeoutError(\"timeout after 5s\")\nTimeoutError: timeout after 5s\n2025-09-07 10:00:06 INFO Retrying connection (1/3)\n\n  File \"/app/db.py\", line 10, in connect\n    raise TimeoutError(\"timeout after 5s\")\nTimeoutError: timeout after 5s\n2025-09-07 10:00:06 INFO Retrying connection (1/3)\n2025-09-07 10:00:11 ERROR Migration failed: relation \"users\" does not exist\n\nTimeoutError: timeout after 5s\n2025-09-07 10:00:06 INFO Retrying connection (1/3)\n2025-09-07 10:00:11 ERROR Migration failed: relation \"users\" does not exist\n2025-09-07 10:00:12 INFO Shutting down\n", "context_keywords": ["timeout", "after", "error", "failed", "timeouterror"], "key_points_keywords": ["database", "connection", "traceback", "most", "recent"]}
